Traceback (most recent call last):
  File "/Users/dawe7269/opt/anaconda3/lib/python3.7/site-packages/jupyter_cache/executors/utils.py", line 56, in single_nb_execution
    record_timing=False,
  File "/Users/dawe7269/opt/anaconda3/lib/python3.7/site-packages/nbclient/client.py", line 1082, in execute
    return NotebookClient(nb=nb, resources=resources, km=km, **kwargs).execute()
  File "/Users/dawe7269/opt/anaconda3/lib/python3.7/site-packages/nbclient/util.py", line 74, in wrapped
    return just_run(coro(*args, **kwargs))
  File "/Users/dawe7269/opt/anaconda3/lib/python3.7/site-packages/nbclient/util.py", line 53, in just_run
    return loop.run_until_complete(coro)
  File "/Users/dawe7269/opt/anaconda3/lib/python3.7/asyncio/base_events.py", line 587, in run_until_complete
    return future.result()
  File "/Users/dawe7269/opt/anaconda3/lib/python3.7/site-packages/nbclient/client.py", line 536, in async_execute
    cell, index, execution_count=self.code_cells_executed + 1
  File "/Users/dawe7269/opt/anaconda3/lib/python3.7/site-packages/nbclient/client.py", line 827, in async_execute_cell
    self._check_raise_for_error(cell, exec_reply)
  File "/Users/dawe7269/opt/anaconda3/lib/python3.7/site-packages/nbclient/client.py", line 735, in _check_raise_for_error
    raise CellExecutionError.from_cell_and_msg(cell, exec_reply['content'])
nbclient.exceptions.CellExecutionError: An error occurred while executing the following cell:
------------------
result = sesolve(H, psi, t_list, e_list)
------------------

[0;31m---------------------------------------------------------------------------[0m
[0;31mUnboundLocalError[0m                         Traceback (most recent call last)
[0;32m<ipython-input-7-fa3b5f74b900>[0m in [0;36m<module>[0;34m[0m
[0;32m----> 1[0;31m [0mresult[0m [0;34m=[0m [0msesolve[0m[0;34m([0m[0mH[0m[0;34m,[0m [0mpsi[0m[0;34m,[0m [0mt_list[0m[0;34m,[0m [0me_list[0m[0;34m)[0m[0;34m[0m[0;34m[0m[0m
[0m
[0;32m~/opt/anaconda3/lib/python3.7/site-packages/qutip/sesolve.py[0m in [0;36msesolve[0;34m(H, psi0, tlist, e_ops, args, options, progress_bar, _safe_mode)[0m
[1;32m    169[0m     res = _generic_ode_solve(func, ode_args, psi0, tlist, e_ops, options,
[1;32m    170[0m                              progress_bar, dims=psi0.dims)
[0;32m--> 171[0;31m     [0;32mif[0m [0me_ops_dict[0m[0;34m:[0m[0;34m[0m[0;34m[0m[0m
[0m[1;32m    172[0m         res.expect = {e: res.expect[n]
[1;32m    173[0m                       for n, e in enumerate(e_ops_dict.keys())}

[0;31mUnboundLocalError[0m: local variable 'e_ops_dict' referenced before assignment
UnboundLocalError: local variable 'e_ops_dict' referenced before assignment

