Traceback (most recent call last):
  File "/Users/dawe7269/opt/anaconda3/lib/python3.7/site-packages/jupyter_cache/executors/utils.py", line 56, in single_nb_execution
    record_timing=False,
  File "/Users/dawe7269/opt/anaconda3/lib/python3.7/site-packages/nbclient/client.py", line 1112, in execute
    return NotebookClient(nb=nb, resources=resources, km=km, **kwargs).execute()
  File "/Users/dawe7269/opt/anaconda3/lib/python3.7/site-packages/nbclient/util.py", line 74, in wrapped
    return just_run(coro(*args, **kwargs))
  File "/Users/dawe7269/opt/anaconda3/lib/python3.7/site-packages/nbclient/util.py", line 53, in just_run
    return loop.run_until_complete(coro)
  File "/Users/dawe7269/opt/anaconda3/lib/python3.7/asyncio/base_events.py", line 587, in run_until_complete
    return future.result()
  File "/Users/dawe7269/opt/anaconda3/lib/python3.7/site-packages/nbclient/client.py", line 554, in async_execute
    cell, index, execution_count=self.code_cells_executed + 1
  File "/Users/dawe7269/opt/anaconda3/lib/python3.7/site-packages/nbclient/client.py", line 857, in async_execute_cell
    self._check_raise_for_error(cell, exec_reply)
  File "/Users/dawe7269/opt/anaconda3/lib/python3.7/site-packages/nbclient/client.py", line 760, in _check_raise_for_error
    raise CellExecutionError.from_cell_and_msg(cell, exec_reply_content)
nbclient.exceptions.CellExecutionError: An error occurred while executing the following cell:
------------------
psip(0)
------------------

[0;31m---------------------------------------------------------------------------[0m
[0;31mNameError[0m                                 Traceback (most recent call last)
[0;32m/var/folders/bx/n6j_5v4x76j6c7f2njx6l_8dgpmt58/T/ipykernel_43119/2874401596.py[0m in [0;36m<module>[0;34m[0m
[0;32m----> 1[0;31m [0mpsip[0m[0;34m([0m[0;36m0[0m[0;34m)[0m[0;34m[0m[0;34m[0m[0m
[0m
[0;32m/var/folders/bx/n6j_5v4x76j6c7f2njx6l_8dgpmt58/T/ipykernel_43119/888028884.py[0m in [0;36mpsip[0;34m(p)[0m
[1;32m      1[0m [0;32mdef[0m [0mpsip[0m[0;34m([0m[0mp[0m[0;34m)[0m[0;34m:[0m[0;34m[0m[0;34m[0m[0m
[0;32m----> 2[0;31m     [0mresult[0m [0;34m=[0m [0mscipy[0m[0;34m.[0m[0mintegrate[0m[0;34m.[0m[0mquad[0m[0;34m([0m[0meipx_Gaussian[0m[0;34m,[0m[0;34m-[0m[0mnumpy[0m[0;34m.[0m[0minf[0m[0;34m,[0m[0mnumpy[0m[0;34m.[0m[0minf[0m[0;34m,[0m[0;34m([0m[0mp[0m[0;34m,[0m[0;36m5[0m[0;34m,[0m[0;36m0.5[0m[0;34m)[0m[0;34m)[0m[0;34m[0m[0;34m[0m[0m
[0m[1;32m      3[0m     [0;32mreturn[0m [0mresult[0m[0;34m[[0m[0;36m0[0m[0;34m][0m[0;34m[0m[0;34m[0m[0m

[0;31mNameError[0m: name 'scipy' is not defined
NameError: name 'scipy' is not defined

